[2025-04-01T19:24:36.499+0000] {taskinstance.py:1956} INFO - Dependencies all met for dep_context=non-requeueable deps ti=<TaskInstance: dag_a.load_data manual__2025-04-01T19:24:32.076029+00:00 [queued]>
[2025-04-01T19:24:36.503+0000] {taskinstance.py:1956} INFO - Dependencies all met for dep_context=requeueable deps ti=<TaskInstance: dag_a.load_data manual__2025-04-01T19:24:32.076029+00:00 [queued]>
[2025-04-01T19:24:36.503+0000] {taskinstance.py:2170} INFO - Starting attempt 1 of 2
[2025-04-01T19:24:36.508+0000] {taskinstance.py:2191} INFO - Executing <Task(PythonOperator): load_data> on 2025-04-01 19:24:32.076029+00:00
[2025-04-01T19:24:36.513+0000] {standard_task_runner.py:60} INFO - Started process 438 to run task
[2025-04-01T19:24:36.515+0000] {standard_task_runner.py:87} INFO - Running: ['***', 'tasks', 'run', 'dag_a', 'load_data', 'manual__2025-04-01T19:24:32.076029+00:00', '--job-id', '26', '--raw', '--subdir', 'DAGS_FOLDER/dynamic_dag.py', '--cfg-path', '/tmp/tmp9qz6j6mb']
[2025-04-01T19:24:36.516+0000] {standard_task_runner.py:88} INFO - Job 26: Subtask load_data
[2025-04-01T19:24:36.539+0000] {task_command.py:423} INFO - Running <TaskInstance: dag_a.load_data manual__2025-04-01T19:24:32.076029+00:00 [running]> on host b0ef469a0134
[2025-04-01T19:24:36.575+0000] {taskinstance.py:2480} INFO - Exporting env vars: AIRFLOW_CTX_DAG_OWNER='***' AIRFLOW_CTX_DAG_ID='dag_a' AIRFLOW_CTX_TASK_ID='load_data' AIRFLOW_CTX_EXECUTION_DATE='2025-04-01T19:24:32.076029+00:00' AIRFLOW_CTX_TRY_NUMBER='1' AIRFLOW_CTX_DAG_RUN_ID='manual__2025-04-01T19:24:32.076029+00:00'
[2025-04-01T19:24:36.580+0000] {base.py:83} INFO - Using connection ID 'postgres_default' for task execution.
[2025-04-01T19:24:36.581+0000] {taskinstance.py:2698} ERROR - Task failed with exception
Traceback (most recent call last):
  File "/home/airflow/.local/lib/python3.8/site-packages/airflow/models/taskinstance.py", line 433, in _execute_task
    result = execute_callable(context=context, **execute_callable_kwargs)
  File "/home/airflow/.local/lib/python3.8/site-packages/airflow/operators/python.py", line 199, in execute
    return_value = self.execute_callable()
  File "/home/airflow/.local/lib/python3.8/site-packages/airflow/operators/python.py", line 216, in execute_callable
    return self.python_callable(*self.op_args, **self.op_kwargs)
  File "/opt/airflow/dags/dynamic_dag.py", line 27, in load_to_postgres
    conn = hook.get_conn()
  File "/home/airflow/.local/lib/python3.8/site-packages/airflow/providers/postgres/hooks/postgres.py", line 158, in get_conn
    self.conn = psycopg2.connect(**conn_args)
  File "/home/airflow/.local/lib/python3.8/site-packages/psycopg2/__init__.py", line 122, in connect
    conn = _connect(dsn, connection_factory=connection_factory, **kwasync)
psycopg2.OperationalError: connection to server at "127.0.0.1", port 5432 failed: Connection refused
	Is the server running on that host and accepting TCP/IP connections?

[2025-04-01T19:24:36.586+0000] {taskinstance.py:1138} INFO - Marking task as UP_FOR_RETRY. dag_id=dag_a, task_id=load_data, execution_date=20250401T192432, start_date=20250401T192436, end_date=20250401T192436
[2025-04-01T19:24:36.592+0000] {standard_task_runner.py:107} ERROR - Failed to execute job 26 for task load_data (connection to server at "127.0.0.1", port 5432 failed: Connection refused
	Is the server running on that host and accepting TCP/IP connections?
; 438)
[2025-04-01T19:24:36.609+0000] {local_task_job_runner.py:234} INFO - Task exited with return code 1
[2025-04-01T19:24:36.624+0000] {taskinstance.py:3280} INFO - 0 downstream tasks scheduled from follow-on schedule check
