[2025-04-01T17:44:57.079+0000] {taskinstance.py:1956} INFO - Dependencies all met for dep_context=non-requeueable deps ti=<TaskInstance: dag_a.unzip_dataset scheduled__2025-03-31T08:00:00+00:00 [queued]>
[2025-04-01T17:44:57.084+0000] {taskinstance.py:1956} INFO - Dependencies all met for dep_context=requeueable deps ti=<TaskInstance: dag_a.unzip_dataset scheduled__2025-03-31T08:00:00+00:00 [queued]>
[2025-04-01T17:44:57.084+0000] {taskinstance.py:2170} INFO - Starting attempt 1 of 2
[2025-04-01T17:44:57.091+0000] {taskinstance.py:2191} INFO - Executing <Task(PythonOperator): unzip_dataset> on 2025-03-31 08:00:00+00:00
[2025-04-01T17:44:57.098+0000] {standard_task_runner.py:60} INFO - Started process 349 to run task
[2025-04-01T17:44:57.100+0000] {standard_task_runner.py:87} INFO - Running: ['***', 'tasks', 'run', 'dag_a', 'unzip_dataset', 'scheduled__2025-03-31T08:00:00+00:00', '--job-id', '9', '--raw', '--subdir', 'DAGS_FOLDER/dynamic_dag.py', '--cfg-path', '/tmp/tmp7sqb4n1s']
[2025-04-01T17:44:57.102+0000] {standard_task_runner.py:88} INFO - Job 9: Subtask unzip_dataset
[2025-04-01T17:44:57.145+0000] {task_command.py:423} INFO - Running <TaskInstance: dag_a.unzip_dataset scheduled__2025-03-31T08:00:00+00:00 [running]> on host f1d361592375
[2025-04-01T17:44:57.177+0000] {taskinstance.py:2480} INFO - Exporting env vars: AIRFLOW_CTX_DAG_OWNER='***' AIRFLOW_CTX_DAG_ID='dag_a' AIRFLOW_CTX_TASK_ID='unzip_dataset' AIRFLOW_CTX_EXECUTION_DATE='2025-03-31T08:00:00+00:00' AIRFLOW_CTX_TRY_NUMBER='1' AIRFLOW_CTX_DAG_RUN_ID='scheduled__2025-03-31T08:00:00+00:00'
[2025-04-01T17:44:57.179+0000] {taskinstance.py:2698} ERROR - Task failed with exception
Traceback (most recent call last):
  File "/home/airflow/.local/lib/python3.8/site-packages/airflow/models/taskinstance.py", line 433, in _execute_task
    result = execute_callable(context=context, **execute_callable_kwargs)
  File "/home/airflow/.local/lib/python3.8/site-packages/airflow/operators/python.py", line 199, in execute
    return_value = self.execute_callable()
  File "/home/airflow/.local/lib/python3.8/site-packages/airflow/operators/python.py", line 216, in execute_callable
    return self.python_callable(*self.op_args, **self.op_kwargs)
  File "/opt/airflow/dags/dynamic_dag.py", line 21, in unzip_dataset
    with zipfile.ZipFile(ZIP_PATH, 'r') as zip_ref:
  File "/usr/local/lib/python3.8/zipfile.py", line 1251, in __init__
    self.fp = io.open(file, filemode)
FileNotFoundError: [Errno 2] No such file or directory: '/opt/airflow/data/technical_task.zip'
[2025-04-01T17:44:57.184+0000] {taskinstance.py:1138} INFO - Marking task as UP_FOR_RETRY. dag_id=dag_a, task_id=unzip_dataset, execution_date=20250331T080000, start_date=20250401T174457, end_date=20250401T174457
[2025-04-01T17:44:57.189+0000] {standard_task_runner.py:107} ERROR - Failed to execute job 9 for task unzip_dataset ([Errno 2] No such file or directory: '/opt/airflow/data/technical_task.zip'; 349)
[2025-04-01T17:44:57.233+0000] {local_task_job_runner.py:234} INFO - Task exited with return code 1
[2025-04-01T17:44:57.246+0000] {taskinstance.py:3280} INFO - 0 downstream tasks scheduled from follow-on schedule check
