[2025-04-02T07:57:55.806+0000] {taskinstance.py:1956} INFO - Dependencies all met for dep_context=non-requeueable deps ti=<TaskInstance: dag_a.load_data manual__2025-04-02T07:57:51.724074+00:00 [queued]>
[2025-04-02T07:57:55.809+0000] {taskinstance.py:1956} INFO - Dependencies all met for dep_context=requeueable deps ti=<TaskInstance: dag_a.load_data manual__2025-04-02T07:57:51.724074+00:00 [queued]>
[2025-04-02T07:57:55.809+0000] {taskinstance.py:2170} INFO - Starting attempt 1 of 2
[2025-04-02T07:57:55.814+0000] {taskinstance.py:2191} INFO - Executing <Task(PythonOperator): load_data> on 2025-04-02 07:57:51.724074+00:00
[2025-04-02T07:57:55.819+0000] {standard_task_runner.py:60} INFO - Started process 887 to run task
[2025-04-02T07:57:55.822+0000] {standard_task_runner.py:87} INFO - Running: ['***', 'tasks', 'run', 'dag_a', 'load_data', 'manual__2025-04-02T07:57:51.724074+00:00', '--job-id', '39', '--raw', '--subdir', 'DAGS_FOLDER/dynamic_dag.py', '--cfg-path', '/tmp/tmp4nierc40']
[2025-04-02T07:57:55.822+0000] {standard_task_runner.py:88} INFO - Job 39: Subtask load_data
[2025-04-02T07:57:55.852+0000] {task_command.py:423} INFO - Running <TaskInstance: dag_a.load_data manual__2025-04-02T07:57:51.724074+00:00 [running]> on host f4b0101fc635
[2025-04-02T07:57:55.892+0000] {taskinstance.py:2480} INFO - Exporting env vars: AIRFLOW_CTX_DAG_OWNER='***' AIRFLOW_CTX_DAG_ID='dag_a' AIRFLOW_CTX_TASK_ID='load_data' AIRFLOW_CTX_EXECUTION_DATE='2025-04-02T07:57:51.724074+00:00' AIRFLOW_CTX_TRY_NUMBER='1' AIRFLOW_CTX_DAG_RUN_ID='manual__2025-04-02T07:57:51.724074+00:00'
[2025-04-02T07:57:55.897+0000] {base.py:83} INFO - Using connection ID 'postgres_default' for task execution.
[2025-04-02T07:57:55.898+0000] {taskinstance.py:2698} ERROR - Task failed with exception
Traceback (most recent call last):
  File "/home/airflow/.local/lib/python3.8/site-packages/airflow/models/taskinstance.py", line 433, in _execute_task
    result = execute_callable(context=context, **execute_callable_kwargs)
  File "/home/airflow/.local/lib/python3.8/site-packages/airflow/operators/python.py", line 199, in execute
    return_value = self.execute_callable()
  File "/home/airflow/.local/lib/python3.8/site-packages/airflow/operators/python.py", line 216, in execute_callable
    return self.python_callable(*self.op_args, **self.op_kwargs)
  File "/opt/airflow/dags/dynamic_dag.py", line 32, in load_to_postgres
    conn = hook.get_conn()
  File "/home/airflow/.local/lib/python3.8/site-packages/airflow/providers/postgres/hooks/postgres.py", line 158, in get_conn
    self.conn = psycopg2.connect(**conn_args)
  File "/home/airflow/.local/lib/python3.8/site-packages/psycopg2/__init__.py", line 122, in connect
    conn = _connect(dsn, connection_factory=connection_factory, **kwasync)
psycopg2.OperationalError: connection to server at "postgres" (172.28.0.3), port 5435 failed: Connection refused
	Is the server running on that host and accepting TCP/IP connections?

[2025-04-02T07:57:55.902+0000] {taskinstance.py:1138} INFO - Marking task as UP_FOR_RETRY. dag_id=dag_a, task_id=load_data, execution_date=20250402T075751, start_date=20250402T075755, end_date=20250402T075755
[2025-04-02T07:57:55.907+0000] {standard_task_runner.py:107} ERROR - Failed to execute job 39 for task load_data (connection to server at "postgres" (172.28.0.3), port 5435 failed: Connection refused
	Is the server running on that host and accepting TCP/IP connections?
; 887)
[2025-04-02T07:57:55.918+0000] {local_task_job_runner.py:234} INFO - Task exited with return code 1
[2025-04-02T07:57:55.928+0000] {taskinstance.py:3280} INFO - 0 downstream tasks scheduled from follow-on schedule check
