[2025-04-02T08:00:03.255+0000] {taskinstance.py:1956} INFO - Dependencies all met for dep_context=non-requeueable deps ti=<TaskInstance: dag_a.load_data scheduled__2025-04-01T08:00:00+00:00 [queued]>
[2025-04-02T08:00:03.259+0000] {taskinstance.py:1956} INFO - Dependencies all met for dep_context=requeueable deps ti=<TaskInstance: dag_a.load_data scheduled__2025-04-01T08:00:00+00:00 [queued]>
[2025-04-02T08:00:03.259+0000] {taskinstance.py:2170} INFO - Starting attempt 1 of 2
[2025-04-02T08:00:03.264+0000] {taskinstance.py:2191} INFO - Executing <Task(PythonOperator): load_data> on 2025-04-01 08:00:00+00:00
[2025-04-02T08:00:03.271+0000] {standard_task_runner.py:60} INFO - Started process 937 to run task
[2025-04-02T08:00:03.274+0000] {standard_task_runner.py:87} INFO - Running: ['***', 'tasks', 'run', 'dag_a', 'load_data', 'scheduled__2025-04-01T08:00:00+00:00', '--job-id', '44', '--raw', '--subdir', 'DAGS_FOLDER/dynamic_dag.py', '--cfg-path', '/tmp/tmpw81za81b']
[2025-04-02T08:00:03.275+0000] {standard_task_runner.py:88} INFO - Job 44: Subtask load_data
[2025-04-02T08:00:03.300+0000] {task_command.py:423} INFO - Running <TaskInstance: dag_a.load_data scheduled__2025-04-01T08:00:00+00:00 [running]> on host f4b0101fc635
[2025-04-02T08:00:03.335+0000] {taskinstance.py:2480} INFO - Exporting env vars: AIRFLOW_CTX_DAG_OWNER='***' AIRFLOW_CTX_DAG_ID='dag_a' AIRFLOW_CTX_TASK_ID='load_data' AIRFLOW_CTX_EXECUTION_DATE='2025-04-01T08:00:00+00:00' AIRFLOW_CTX_TRY_NUMBER='1' AIRFLOW_CTX_DAG_RUN_ID='scheduled__2025-04-01T08:00:00+00:00'
[2025-04-02T08:00:03.340+0000] {base.py:83} INFO - Using connection ID 'postgres_default' for task execution.
[2025-04-02T08:00:03.341+0000] {taskinstance.py:2698} ERROR - Task failed with exception
Traceback (most recent call last):
  File "/home/airflow/.local/lib/python3.8/site-packages/airflow/models/taskinstance.py", line 433, in _execute_task
    result = execute_callable(context=context, **execute_callable_kwargs)
  File "/home/airflow/.local/lib/python3.8/site-packages/airflow/operators/python.py", line 199, in execute
    return_value = self.execute_callable()
  File "/home/airflow/.local/lib/python3.8/site-packages/airflow/operators/python.py", line 216, in execute_callable
    return self.python_callable(*self.op_args, **self.op_kwargs)
  File "/opt/airflow/dags/dynamic_dag.py", line 32, in load_to_postgres
    conn = hook.get_conn()
  File "/home/airflow/.local/lib/python3.8/site-packages/airflow/providers/postgres/hooks/postgres.py", line 158, in get_conn
    self.conn = psycopg2.connect(**conn_args)
  File "/home/airflow/.local/lib/python3.8/site-packages/psycopg2/__init__.py", line 122, in connect
    conn = _connect(dsn, connection_factory=connection_factory, **kwasync)
psycopg2.OperationalError: connection to server at "postgres" (172.28.0.3), port 5435 failed: Connection refused
	Is the server running on that host and accepting TCP/IP connections?

[2025-04-02T08:00:03.347+0000] {taskinstance.py:1138} INFO - Marking task as UP_FOR_RETRY. dag_id=dag_a, task_id=load_data, execution_date=20250401T080000, start_date=20250402T080003, end_date=20250402T080003
[2025-04-02T08:00:03.353+0000] {standard_task_runner.py:107} ERROR - Failed to execute job 44 for task load_data (connection to server at "postgres" (172.28.0.3), port 5435 failed: Connection refused
	Is the server running on that host and accepting TCP/IP connections?
; 937)
[2025-04-02T08:00:03.365+0000] {local_task_job_runner.py:234} INFO - Task exited with return code 1
[2025-04-02T08:00:03.375+0000] {taskinstance.py:3280} INFO - 0 downstream tasks scheduled from follow-on schedule check
[2025-04-02T10:25:59.262+0000] {taskinstance.py:1956} INFO - Dependencies all met for dep_context=non-requeueable deps ti=<TaskInstance: dag_a.load_data scheduled__2025-04-01T08:00:00+00:00 [queued]>
[2025-04-02T10:25:59.267+0000] {taskinstance.py:1956} INFO - Dependencies all met for dep_context=requeueable deps ti=<TaskInstance: dag_a.load_data scheduled__2025-04-01T08:00:00+00:00 [queued]>
[2025-04-02T10:25:59.267+0000] {taskinstance.py:2170} INFO - Starting attempt 1 of 2
[2025-04-02T10:25:59.277+0000] {taskinstance.py:2191} INFO - Executing <Task(PythonOperator): load_data> on 2025-04-01 08:00:00+00:00
[2025-04-02T10:25:59.284+0000] {standard_task_runner.py:60} INFO - Started process 141 to run task
[2025-04-02T10:25:59.289+0000] {standard_task_runner.py:87} INFO - Running: ['***', 'tasks', 'run', 'dag_a', 'load_data', 'scheduled__2025-04-01T08:00:00+00:00', '--job-id', '74', '--raw', '--subdir', 'DAGS_FOLDER/dynamic_dag.py', '--cfg-path', '/tmp/tmpek0uufta']
[2025-04-02T10:25:59.290+0000] {standard_task_runner.py:88} INFO - Job 74: Subtask load_data
[2025-04-02T10:25:59.326+0000] {task_command.py:423} INFO - Running <TaskInstance: dag_a.load_data scheduled__2025-04-01T08:00:00+00:00 [running]> on host 247d35c01501
[2025-04-02T10:25:59.372+0000] {taskinstance.py:2480} INFO - Exporting env vars: AIRFLOW_CTX_DAG_OWNER='***' AIRFLOW_CTX_DAG_ID='dag_a' AIRFLOW_CTX_TASK_ID='load_data' AIRFLOW_CTX_EXECUTION_DATE='2025-04-01T08:00:00+00:00' AIRFLOW_CTX_TRY_NUMBER='1' AIRFLOW_CTX_DAG_RUN_ID='scheduled__2025-04-01T08:00:00+00:00'
[2025-04-02T10:25:59.378+0000] {base.py:83} INFO - Using connection ID 'postgres_default' for task execution.
[2025-04-02T10:25:59.480+0000] {python.py:201} INFO - Done. Returned value was: None
[2025-04-02T10:25:59.485+0000] {taskinstance.py:1138} INFO - Marking task as SUCCESS. dag_id=dag_a, task_id=load_data, execution_date=20250401T080000, start_date=20250402T102559, end_date=20250402T102559
[2025-04-02T10:25:59.501+0000] {local_task_job_runner.py:234} INFO - Task exited with return code 0
[2025-04-02T10:25:59.510+0000] {taskinstance.py:3280} INFO - 0 downstream tasks scheduled from follow-on schedule check
